<?xml version="1.0" encoding="utf-8"?>
<!-- This URDF was automatically created by SolidWorks to URDF Exporter! Originally created by Stephen Brawner (brawner@gmail.com) 
     Commit Version: 1.6.0-4-g7f85cfe  Build Version: 1.6.7995.38578
     For more information, please see http://wiki.ros.org/sw_urdf_exporter -->
<robot
  name="myCobot_Pro_600_230708">
  <link
    name="base_link">
    <inertial>
      <origin
        xyz="0.0079271 -0.00021999 0.079876"
        rpy="0 0 0" />
      <mass
        value="0.67481" />
      <inertia
        ixx="0.0016132"
        ixy="-8.9696E-06"
        ixz="-6.843E-05"
        iyy="0.0015205"
        iyz="3.7354E-07"
        izz="0.0009498" />
    </inertial>
    <visual>
      <origin
        xyz="0 0 0"
        rpy="0 0 0" />
      <geometry>
        <mesh
          filename="meshes\base_link.STL" />
      </geometry>
      <material
        name="">
        <color
          rgba="0.79216 0.81961 0.93333 1" />
      </material>
    </visual>
    <collision>
      <origin
        xyz="0 0 0"
        rpy="0 0 0" />
      <geometry>
        <mesh
          filename="meshes\base_link.STL" />
      </geometry>
    </collision>
  </link>
  <link
    name="link1">
    <inertial>
      <origin
        xyz="2.1277E-06 -0.031707 0.040848"
        rpy="0 0 0" />
      <mass
        value="0.233" />
      <inertia
        ixx="0.00035212"
        ixy="7.264E-09"
        ixz="-6.7101E-09"
        iyy="0.00022966"
        iyz="5.3637E-05"
        izz="0.00033375" />
    </inertial>
    <visual>
      <origin
        xyz="0 0 0"
        rpy="0 0 0" />
      <geometry>
        <mesh
          filename="meshes\link1.STL" />
      </geometry>
      <material
        name="">
        <color
          rgba="0.79216 0.81961 0.93333 1" />
      </material>
    </visual>
    <collision>
      <origin
        xyz="0 0 0"
        rpy="0 0 0" />
      <geometry>
        <mesh
          filename="meshes\link1.STL" />
      </geometry>
    </collision>
  </link>
  <joint
    name="Joint1"
    type="revolute">
    <origin
      xyz="0.0010791 0 0.1613"
      rpy="0 0 0" />
    <parent
      link="base_link" />
    <child
      link="link1" />
    <axis
      xyz="0 0 1" />
    <limit
      lower="-3.14"
      upper="3.14"
      effort="0"
      velocity="0" />
  </joint>
  <link
    name="Link2">
    <inertial>
      <origin
        xyz="-0.12544 -1.0885E-07 0.045584"
        rpy="0 0 0" />
      <mass
        value="0.46759" />
      <inertia
        ixx="0.00029513"
        ixy="2.1107E-07"
        ixz="6.2176E-08"
        iyy="0.0033213"
        iyz="9.2619E-09"
        izz="0.003398" />
    </inertial>
    <visual>
      <origin
        xyz="0 0 0"
        rpy="0 0 0" />
      <geometry>
        <mesh
          filename="meshes\Link2.STL" />
      </geometry>
      <material
        name="">
        <color
          rgba="0.79216 0.81961 0.93333 1" />
      </material>
    </visual>
    <collision>
      <origin
        xyz="0 0 0"
        rpy="0 0 0" />
      <geometry>
        <mesh
          filename="meshes\Link2.STL" />
      </geometry>
    </collision>
  </link>
  <joint
    name="Joint2"
    type="revolute">
    <origin
      xyz="0 -0.0815 0.048"
      rpy="1.5708 1.5708 0" />
    <parent
      link="link1" />
    <child
      link="Link2" />
    <axis
      xyz="0 0 1" />
    <limit
      lower="-4.71"
      upper="1.57"
      effort="0"
      velocity="0" />
  </joint>
  <link
    name="Link3">
    <inertial>
      <origin
        xyz="-0.1280957372574 0.000196679934896904 -0.0739770755509075"
        rpy="0 0 0" />
      <mass
        value="0.610849978069838" />
      <inertia
        ixx="0.000343678370714938"
        ixy="1.32490637719178E-05"
        ixz="-0.000162869580771304"
        iyy="0.00397744693740067"
        iyz="2.68960234213695E-07"
        izz="0.00404466439515321" />
    </inertial>
    <visual>
      <origin
        xyz="0 0 0"
        rpy="0 0 0" />
      <geometry>
        <mesh
          filename="meshes\Link3.STL" />
      </geometry>
      <material
        name="">
        <color
          rgba="0.792156862745098 0.819607843137255 0.933333333333333 1" />
      </material>
    </visual>
    <collision>
      <origin
        xyz="0 0 0"
        rpy="0 0 0" />
      <geometry>
        <mesh
          filename="meshes\Link3.STL" />
      </geometry>
    </collision>
  </link>
  <joint
    name="Joint3"
    type="revolute">
    <origin
      xyz="-0.25 0 0.0078003"
      rpy="0 0 0" />
    <parent
      link="Link2" />
    <child
      link="Link3" />
    <axis
      xyz="0 0 1" />
    <limit
      lower="-2.61"
      upper="2.61"
      effort="0"
      velocity="0" />
  </joint>
  <link
    name="Link4">
    <inertial>
      <origin
        xyz="0.000451153554830226 -0.0197043732761449 0.042013063084008"
        rpy="0 0 0" />
      <mass
        value="0.143946980002621" />
      <inertia
        ixx="7.66118811015413E-05"
        ixy="6.23901181466462E-07"
        ixz="-1.05177948304585E-07"
        iyy="9.69506366426813E-05"
        iyz="5.42656388625233E-06"
        izz="6.51760979548038E-05" />
    </inertial>
    <visual>
      <origin
        xyz="0 0 0"
        rpy="0 0 0" />
      <geometry>
        <mesh
          filename="meshes\Link4.STL" />
      </geometry>
      <material
        name="">
        <color
          rgba="0.792156862745098 0.819607843137255 0.933333333333333 1" />
      </material>
    </visual>
    <collision>
      <origin
        xyz="0 0 0"
        rpy="0 0 0" />
      <geometry>
        <mesh
          filename="meshes\Link4.STL" />
      </geometry>
    </collision>
  </link>
  <joint
    name="Joint4"
    type="revolute">
    <origin
      xyz="-0.25 0 -0.0253"
      rpy="0 0 -1.5708" />
    <parent
      link="Link3" />
    <child
      link="Link4" />
    <axis
      xyz="0 0 1" />
    <limit
      lower="-4.53"
      upper="1.39"
      effort="0"
      velocity="0" />
  </joint>
  <link
    name="Link5">
    <inertial>
      <origin
        xyz="0.0205010906761461 0.00010373072039811 0.0509688530646235"
        rpy="0 0 0" />
      <mass
        value="0.209121230720947" />
      <inertia
        ixx="0.000140702156886984"
        ixy="-3.5192188177773E-07"
        ixz="-1.7138270492691E-05"
        iyy="0.000117850051515568"
        iyz="-1.30797771287935E-07"
        izz="0.000110784178232256" />
    </inertial>
    <visual>
      <origin
        xyz="0 0 0"
        rpy="0 0 0" />
      <geometry>
        <mesh
          filename="meshes\Link5.STL" />
      </geometry>
      <material
        name="">
        <color
          rgba="0.792156862745098 0.819607843137255 0.933333333333333 1" />
      </material>
    </visual>
    <collision>
      <origin
        xyz="0 0 0"
        rpy="0 0 0" />
      <geometry>
        <mesh
          filename="meshes\Link5.STL" />
      </geometry>
    </collision>
  </link>
  <joint
    name="Joint5"
    type="revolute">
    <origin
      xyz="0 -0.0537 0.0455"
      rpy="1.5708 -1.5708 0" />
    <parent
      link="Link4" />
    <child
      link="Link5" />
    <axis
      xyz="0 0 1" />
    <limit
      lower="-3.03"
      upper="3.03"
      effort="0"
      velocity="0" />
  </joint>
  <link
    name="Link6">
    <inertial>
      <origin
        xyz="-3.6855E-16 3.9862E-09 0.0039"
        rpy="0 0 0" />
      <mass
        value="0.0015438" />
      <inertia
        ixx="7.7393E-07"
        ixy="2.9626E-27"
        ixz="2.9025E-21"
        iyy="7.7393E-07"
        iyz="7.7504E-13"
        izz="1.5322E-06" />
    </inertial>
    <visual>
      <origin
        xyz="0 0 0"
        rpy="0 0 0" />
      <geometry>
        <mesh
          filename="meshes\Link6.STL" />
      </geometry>
      <material
        name="">
        <color
          rgba="0.79216 0.81961 0.93333 1" />
      </material>
    </visual>
    <collision>
      <origin
        xyz="0 0 0"
        rpy="0 0 0" />
      <geometry>
        <mesh
          filename="meshes\Link6.STL" />
      </geometry>
    </collision>
  </link>
  <joint
    name="Joint6"
    type="revolute">
    <origin
      xyz="0.053197 0 0.0533"
      rpy="-1.5708 0 -1.5708" />
    <parent
      link="Link5" />
    <child
      link="Link6" />
    <axis
      xyz="0 0 1" />
    <limit
      lower="-2.93"
      upper="2.93"
      effort="0"
      velocity="0" />
  </joint>
</robot>